2021-07-26 17:02:51,224 DEBUG    root            Loaded Command Group: ['gcloud', 'ai_platform']
2021-07-26 17:02:51,226 DEBUG    root            Loaded Command Group: ['gcloud', 'ai-platform', 'local']
2021-07-26 17:02:51,228 DEBUG    root            Loaded Command Group: ['gcloud', 'ai-platform', 'local', 'train']
2021-07-26 17:02:51,235 DEBUG    root            Running [gcloud.ai-platform.local.train] with arguments: [--module-name: "trainer.task", --package-path: "trainer"]
2021-07-26 17:02:53,505 INFO     root            launching training process:
command: /opt/conda/bin/python -m trainer.task
 config: {
  "cluster": {},
  "environment": "cloud",
  "job": {
    "args": [],
    "job_name": "trainer.task"
  },
  "task": {}
}
2021-07-26 17:02:55,799 DEBUG    root            Executing command: ['/opt/conda/bin/python', '-m', 'trainer.task']
2021-07-26 17:02:59,046 INFO     root            Display format: "default"
2021-07-26 17:02:59,047 DEBUG    root            (gcloud.ai-platform.local.train) 
Traceback (most recent call last):
  File "/usr/lib/google-cloud-sdk/lib/googlecloudsdk/calliope/cli.py", line 984, in Execute
    resources = calliope_command.Run(cli=self, args=args)
  File "/usr/lib/google-cloud-sdk/lib/googlecloudsdk/calliope/backend.py", line 815, in Run
    raise exceptions.ExitCodeNoError(exit_code=command_instance.exit_code)
googlecloudsdk.calliope.exceptions.ExitCodeNoError
